Workbook

Sheet Read Me
A1: Mira Trading Ltd. — Mock ERP Workbook
A2: 6-month sample dataset for the SAP portfolio project (Jan-Jun)
A5: How to use this workbook:
A6: 1. Chart of Accounts / Cost Centers — reference tables (master data).
A7: 2. Journal Entries — the full double-entry transaction log for Jan-Jun. This is your 'FI' data.
A8: 3. Trial Balance — auto-calculated from Journal Entries via SUMIFS formulas, one Net column per month.
A9: 4. P&L — auto-calculated income statement by month with a Revenue/Net Income trend chart. Use this for your dashboard and case study.
A10: 5. Cost Center Reporting (BW mock) — Cost Center x Category x Month, standing in for a BW query/InfoProvider.
A12: All blue text = source data (journal entries). All black text = formulas that recalculate automatically.
A13: Change any journal entry amount and the Trial Balance, P&L, and Cost Center Reporting sheets update automatically.
A15: Assumptions: fictional company, EUR currency, single company code, 3 cost centers, 6 fiscal periods (Jan-Jun) shown to illustrate a realistic trend rather than a single before/after snapshot.

Sheet Chart of Accounts
A1: Chart of Accounts
A2: Master data — GL accounts used by Mira Trading Ltd.
A4: GL Account | B4: Description | C4: Type | D4: Category
A5: 100000 | B5: Cash / Bank | C5: Balance Sheet | D5: Asset
A6: 120000 | B6: Accounts Receivable | C6: Balance Sheet | D6: Asset
A7: 160000 | B7: Inventory | C7: Balance Sheet | D7: Asset
A8: 170000 | B8: Accumulated Depreciation | C8: Balance Sheet | D8: Contra-Asset
A9: 200000 | B9: Accounts Payable | C9: Balance Sheet | D9: Liability
A10: 210000 | B10: Accrued Liabilities | C10: Balance Sheet | D10: Liability
A11: 300000 | B11: Retained Earnings | C11: Balance Sheet | D11: Equity
A12: 310000 | B12: Owner's Capital | C12: Balance Sheet | D12: Equity
A13: 400000 | B13: Sales Revenue | C13: P&L | D13: Revenue
A14: 500000 | B14: Cost of Goods Sold | C14: P&L | D14: COGS
A15: 600000 | B15: Salaries Expense | C15: P&L | D15: Opex
A16: 610000 | B16: Rent Expense | C16: P&L | D16: Opex
... A20: 650000 | B20: Marketing Expense | C20: P&L | D20: Opex

Sheet Cost Centers
A1: Cost Centers
A2: Master data
A4: Cost Center | B4: Name
A5: CC-100 | B5: Sales
A6: CC-200 | B6: Warehouse
A7: CC-300 | B7: Admin & Finance

Sheet Journal Entries
A1: Journal Entries
A2: Double-entry transaction log — January through June
A4: JE ID | B4: Date | C4: Month | D4: Month # | E4: GL Account | F4: Description | G4: Cost Center | H4: Party | I4: Debit | J4: Credit
A5: JE-OPEN | B5: 2026-01-01 | C5: Jan | D5: 1 | E5: 100000 | F5: Owner's initial capital contribution | G5: CC-300 | H5: Owner | I5: 20000 | J5: 0
A6: JE-OPEN | B6: 2026-01-01 | C6: Jan | D6: 1 | E6: 310000 | F6: Owner's initial capital contribution | G6: CC-300 | H6: Owner | I6: 0 | J6: 20000
A7: JE-Jan01 | B7: 2026-01-05 | C7: Jan | D7: 1 | E7: 120000 | F7: Invoice - Customer A | G7: CC-100 | H7: Customer A | I7: 11000 | J7: 0
A8: JE-Jan01 | B8: 2026-01-05 | C8: Jan | D8: 1 | E8: 400000 | F8: Invoice - Customer A | G8: CC-100 | H8: Customer A | I8: 0 | J8: 11000
A9: JE-Jan02 | B9: 2026-01-22 | C9: Jan | D9: 1 | E9: 120000 | F9: Invoice - Customer B | G9: CC-100 | H9: Customer B | I9: 7000 | J9: 0
A10: JE-Jan02 | B10: 2026-01-22 | C10: Jan | D10: 1 | E10: 400000 | F10: Invoice - Customer B | G10: CC-100 | H10: Customer B | I10: 0 | J10: 7000
A11: JE-Jan03 | B11: 2026-01-08 | C11: Jan | D11: 1 | E11: 500000 | F11: Inventory purchase - Vendor X | G11: CC-200 | H11: Vendor X | I11: 7500 | J11: 0
A12: JE-Jan03 | B12: 2026-01-08 | C12: Jan | D12: 1 | E12: 200000 | F12: Inventory purchase - Vendor X | G12: CC-200 | H12: Vendor X | I12: 0 | J12: 7500
A13: JE-Jan04 | B13: 2026-01-19 | C13: Jan | D13: 1 | E13: 500000 | F13: Inventory purchase - Vendor Y | G13: CC-200 | H13: Vendor Y | I13: 4500 | J13: 0
A14: JE-Jan04 | B14: 2026-01-19 | C14: Jan | D14: 1 | E14: 200000 | F14: Inventory purchase - Vendor Y | G14: CC-200 | H14: Vendor Y | I14: 0 | J14: 4500
A15: JE-Jan05 | B15: 2026-01-15 | C15: Jan | D15: 1 | E15: 610000 | F15: Jan office rent | G15: CC-300 | H15: Landlord Co. | I15: 3200 | J15: 0
A16: JE-Jan05 | B16: 2026-01-15 | C16: Jan | D16: 1 | E16: 200000 | F16: Jan office rent | G16: CC-300 | H16: Landlord Co. | I16: 0 | J16: 3200
... A184: JE-Jun14 | B184: 2026-06-30 | C184: Jun | D184: 6 | E184: 100000 | F184: Vendor payments made (partial settlement) | G184: CC-300 | H184: Multiple Vendors | I184: 0 | J184: 28500
H185: TOTAL | I185: =SUM(I5:I184) -> 894550 | J185: =SUM(J5:J184) -> 894550

Sheet Trial Balance
A1: Trial Balance
A2: Net balance (Debit-Credit) by GL account, auto-calculated per month via SUMIFS
A4: GL Account | B4: Description | C4: Jan Net | D4: Feb Net | E4: Mar Net | F4: Apr Net | G4: May Net | H4: Jun Net
A5: ='Chart of Accounts'!A5 -> 100000 | B5: ='Chart of Accounts'!B5 -> Cash / Bank | C5: =SUMIFS('Journal Entries'!$I$5:$I$184,'Journal Entries'!$E$5:$E$184,$A5,'Journal Entries'!$D$5:$D$184,"<=1")-SUMIFS('Journal Entries'!$J$5:$J$184,'Journal Entries'!$E$5:$E$184,$A5,'Journal Entries'!$D$5:$D$184,"<=1") -> 7900 | D5: =SUMIFS('Journal Entries'!$I$5:$I$184,'Journal Entries'!$E$5:$E$184,$A5,'Journal Entries'!$D$5:$D$184,"<=2")-SUMIFS('Journal Entries'!$J$5:$J$184,'Journal Entries'!$E$5:$E$184,$A5,'Journal Entries'!$D$5:$D$184,"<=2") -> -5150 | E5: =SUMIFS('Journal Entries'!$I$5:$I$184,'Journal Entries'!$E$5:$E$184,$A5,'Journal Entries'!$D$5:$D$184,"<=3")-SUMIFS('Journal Entries'!$J$5:$J$184,'Journal Entries'!$E$5:$E$184,$A5,'Journal Entries'!$D$5:$D$184,"<=3") -> -7100 | F5: =SUMIFS('Journal Entries'!$I$5:$I$184,'Journal Entries'!$E$5:$E$184,$A5,'Journal Entries'!$D$5:$D$184,"<=4")-SUMIFS('Journal Entries'!$J$5:$J$184,'Journal Entries'!$E$5:$E$184,$A5,'Journal Entries'!$D$5:$D$184,"<=4") -> -7050 | G5: =SUMIFS('Journal Entries'!$I$5:$I$184,'Journal Entries'!$E$5:$E$184,$A5,'Journal Entries'!$D$5:$D$184,"<=5")-SUMIFS('Journal Entries'!$J$5:$J$184,'Journal Entries'!$E$5:$E$184,$A5,'Journal Entries'!$D$5:$D$184,"<=5") -> -4050 | H5: =SUMIFS('Journal Entries'!$I$5:$I$184,'Journal Entries'!$E$5:$E$184,$A5,'Journal Entries'!$D$5:$D$184,"<=6")-SUMIFS('Journal Entries'!$J$5:$J$184,'Journal Entries'!$E$5:$E$184,$A5,'Journal Entries'!$D$5:$D$184,"<=6") -> 1100
A6: ='Chart of Accounts'!A6 -> 120000 | B6: ='Chart of Accounts'!B6 -> Accounts Receivable | C6: =SUMIFS('Journal Entries'!$I$5:$I$184,'Journal Entries'!$E$5:$E$184,$A6,'Journal Entries'!$D$5:$D$184,"<=1")-SUMIFS('Journal Entries'!$J$5:$J$184,'Journal Entries'!$E$5:$E$184,$A6,'Journal Entries'!$D$5:$D$184,"<=1") -> 4500 | D6: =SUMIFS('Journal Entries'!$I$5:$I$184,'Journal Entries'!$E$5:$E$184,$A6,'Journal Entries'!$D$5:$D$184,"<=2")-SUMIFS('Journal Entries'!$J$5:$J$184,'Journal Entries'!$E$5:$E$184,$A6,'Journal Entries'!$D$5:$D$184,"<=2") -> 10250 | E6: =SUMIFS('Journal Entries'!$I$5:$I$184,'Journal Entries'!$E$5:$E$184,$A6,'Journal Entries'!$D$5:$D$184,"<=3")-SUMIFS('Journal Entries'!$J$5:$J$184,'Journal Entries'!$E$5:$E$184,$A6,'Journal Entries'!$D$5:$D$184,"<=3") -> 22450 | F6: =SUMIFS('Journal Entries'!$I$5:$I$184,'Journal Entries'!$E$5:$E$184,$A6,'Journal Entries'!$D$5:$D$184,"<=4")-SUMIFS('Journal Entries'!$J$5:$J$184,'Journal Entries'!$E$5:$E$184,$A6,'Journal Entries'!$D$5:$D$184,"<=4") -> 35450 | G6: =SUMIFS('Journal Entries'!$I$5:$I$184,'Journal Entries'!$E$5:$E$184,$A6,'Journal Entries'!$D$5:$D$184,"<=5")-SUMIFS('Journal Entries'!$J$5:$J$184,'Journal Entries'!$E$5:$E$184,$A6,'Journal Entries'!$D$5:$D$184,"<=5") -> 49950 | H6: =SUMIFS('Journal Entries'!$I$5:$I$184,'Journal Entries'!$E$5:$E$184,$A6,'Journal Entries'!$D$5:$D$184,"<=6")-SUMIFS('Journal Entries'!$J$5:$J$184,'Journal Entries'!$E$5:$E$184,$A6,'Journal Entries'!$D$5:$D$184,"<=6") -> 65700
A7: ='Chart of Accounts'!A7 -> 160000 | B7: ='Chart of Accounts'!B7 -> Inventory | C7: =SUMIFS('Journal Entries'!$I$5:$I$184,'Journal Entries'!$E$5:$E$184,$A7,'Journal Entries'!$D$5:$D$184,"<=1")-SUMIFS('Journal Entries'!$J$5:$J$184,'Journal Entries'!$E$5:$E$184,$A7,'Journal Entries'!$D$5:$D$184,"<=1") -> 0 | D7: =SUMIFS('Journal Entries'!$I$5:$I$184,'Journal Entries'!$E$5:$E$184,$A7,'Journal Entries'!$D$5:$D$184,"<=2")-SUMIFS('Journal Entries'!$J$5:$J$184,'Journal Entries'!$E$5:$E$184,$A7,'Journal Entries'!$D$5:$D$184,"<=2") -> 0 | E7: =SUMIFS('Journal Entries'!$I$5:$I$184,'Journal Entries'!$E$5:$E$184,$A7,'Journal Entries'!$D$5:$D$184,"<=3")-SUMIFS('Journal Entries'!$J$5:$J$184,'Journal Entries'!$E$5:$E$184,$A7,'Journal Entries'!$D$5:$D$184,"<=3") -> 0 | F7: =SUMIFS('Journal Entries'!$I$5:$I$184,'Journal Entries'!$E$5:$E$184,$A7,'Journal Entries'!$D$5:$D$184,"<=4")-SUMIFS('Journal Entries'!$J$5:$J$184,'Journal Entries'!$E$5:$E$184,$A7,'Journal Entries'!$D$5:$D$184,"<=4") -> 0 | G7: =SUMIFS('Journal Entries'!$I$5:$I$184,'Journal Entries'!$E$5:$E$184,$A7,'Journal Entries'!$D$5:$D$184,"<=5")-SUMIFS('Journal Entries'!$J$5:$J$184,'Journal Entries'!$E$5:$E$184,$A7,'Journal Entries'!$D$5:$D$184,"<=5") -> 0 | H7: =SUMIFS('Journal Entries'!$I$5:$I$184,'Journal Entries'!$E$5:$E$184,$A7,'Journal Entries'!$D$5:$D$184,"<=6")-SUMIFS('Journal Entries'!$J$5:$J$184,'Journal Entries'!$E$5:$E$184,$A7,'Journal Entries'!$D$5:$D$184,"<=6") -> 0
A8: ='Chart of Accounts'!A8 -> 170000 | B8: ='Chart of Accounts'!B8 -> Accumulated Depreciation | C8: =SUMIFS('Journal Entries'!$I$5:$I$184,'Journal Entries'!$E$5:$E$184,$A8,'Journal Entries'!$D$5:$D$184,"<=1")-SUMIFS('Journal Entries'!$J$5:$J$184,'Journal Entries'!$E$5:$E$184,$A8,'Journal Entries'!$D$5:$D$184,"<=1") -> -900 | D8: =SUMIFS('Journal Entries'!$I$5:$I$184,'Journal Entries'!$E$5:$E$184,$A8,'Journal Entries'!$D$5:$D$184,"<=2")-SUMIFS('Journal Entries'!$J$5:$J$184,'Journal Entries'!$E$5:$E$184,$A8,'Journal Entries'!$D$5:$D$184,"<=2") -> -1800 | E8: =SUMIFS('Journal Entries'!$I$5:$I$184,'Journal Entries'!$E$5:$E$184,$A8,'Journal Entries'!$D$5:$D$184,"<=3")-SUMIFS('Journal Entries'!$J$5:$J$184,'Journal Entries'!$E$5:$E$184,$A8,'Journal Entries'!$D$5:$D$184,"<=3") -> -2700 | F8: =SUMIFS('Journal Entries'!$I$5:$I$184,'Journal Entries'!$E$5:$E$184,$A8,'Journal Entries'!$D$5:$D$184,"<=4")-SUMIFS('Journal Entries'!$J$5:$J$184,'Journal Entries'!$E$5:$E$184,$A8,'Journal Entries'!$D$5:$D$184,"<=4") -> -3600 | G8: =SUMIFS('Journal Entries'!$I$5:$I$184,'Journal Entries'!$E$5:$E$184,$A8,'Journal Entries'!$D$5:$D$184,"<=5")-SUMIFS('Journal Entries'!$J$5:$J$184,'Journal Entries'!$E$5:$E$184,$A8,'Journal Entries'!$D$5:$D$184,"<=5") -> -4500 | H8: =SUMIFS('Journal Entries'!$I$5:$I$184,'Journal Entries'!$E$5:$E$184,$A8,'Journal Entries'!$D$5:$D$184,"<=6")-SUMIFS('Journal Entries'!$J$5:$J$184,'Journal Entries'!$E$5:$E$184,$A8,'Journal Entries'!$D$5:$D$184,"<=6") -> -5400
A9: ='Chart of Accounts'!A9 -> 200000 | B9: ='Chart of Accounts'!B9 -> Accounts Payable | C9: =SUMIFS('Journal Entries'!$I$5:$I$184,'Journal Entries'!$E$5:$E$184,$A9,'Journal Entries'!$D$5:$D$184,"<=1")-SUMIFS('Journal Entries'!$J$5:$J$184,'Journal Entries'!$E$5:$E$184,$A9,'Journal Entries'!$D$5:$D$184,"<=1") -> -5150 | D9: =SUMIFS('Journal Entries'!$I$5:$I$184,'Journal Entries'!$E$5:$E$184,$A9,'Journal Entries'!$D$5:$D$184,"<=2")-SUMIFS('Journal Entries'!$J$5:$J$184,'Journal Entries'!$E$5:$E$184,$A9,'Journal Entries'!$D$5:$D$184,"<=2") -> -12300 | E9: =SUMIFS('Journal Entries'!$I$5:$I$184,'Journal Entries'!$E$5:$E$184,$A9,'Journal Entries'!$D$5:$D$184,"<=3")-SUMIFS('Journal Entries'!$J$5:$J$184,'Journal Entries'!$E$5:$E$184,$A9,'Journal Entries'!$D$5:$D$184,"<=3") -> -23030 | F9: =SUMIFS('Journal Entries'!$I$5:$I$184,'Journal Entries'!$E$5:$E$184,$A9,'Journal Entries'!$D$5:$D$184,"<=4")-SUMIFS('Journal Entries'!$J$5:$J$184,'Journal Entries'!$E$5:$E$184,$A9,'Journal Entries'!$D$5:$D$184,"<=4") -> -33900 | G9: =SUMIFS('Journal Entries'!$I$5:$I$184,'Journal Entries'!$E$5:$E$184,$A9,'Journal Entries'!$D$5:$D$184,"<=5")-SUMIFS('Journal Entries'!$J$5:$J$184,'Journal Entries'!$E$5:$E$184,$A9,'Journal Entries'!$D$5:$D$184,"<=5") -> -45450 | H9: =SUMIFS('Journal Entries'!$I$5:$I$184,'Journal Entries'!$E$5:$E$184,$A9,'Journal Entries'!$D$5:$D$184,"<=6")-SUMIFS('Journal Entries'!$J$5:$J$184,'Journal Entries'!$E$5:$E$184,$A9,'Journal Entries'!$D$5:$D$184,"<=6") -> -57700
A10: ='Chart of Accounts'!A10 -> 210000 | B10: ='Chart of Accounts'!B10 -> Accrued Liabilities | C10: =SUMIFS('Journal Entries'!$I$5:$I$184,'Journal Entries'!$E$5:$E$184,$A10,'Journal Entries'!$D$5:$D$184,"<=1")-SUMIFS('Journal Entries'!$J$5:$J$184,'Journal Entries'!$E$5:$E$184,$A10,'Journal Entries'!$D$5:$D$184,"<=1") -> -200 | D10: =SUMIFS('Journal Entries'!$I$5:$I$184,'Journal Entries'!$E$5:$E$184,$A10,'Journal Entries'!$D$5:$D$184,"<=2")-SUMIFS('Journal Entries'!$J$5:$J$184,'Journal Entries'!$E$5:$E$184,$A10,'Journal Entries'!$D$5:$D$184,"<=2") -> -450 | E10: =SUMIFS('Journal Entries'!$I$5:$I$184,'Journal Entries'!$E$5:$E$184,$A10,'Journal Entries'!$D$5:$D$184,"<=3")-SUMIFS('Journal Entries'!$J$5:$J$184,'Journal Entries'!$E$5:$E$184,$A10,'Journal Entries'!$D$5:$D$184,"<=3") -> -750 | F10: =SUMIFS('Journal Entries'!$I$5:$I$184,'Journal Entries'!$E$5:$E$184,$A10,'Journal Entries'!$D$5:$D$184,"<=4")-SUMIFS('Journal Entries'!$J$5:$J$184,'Journal Entries'!$E$5:$E$184,$A10,'Journal Entries'!$D$5:$D$184,"<=4") -> -950 | G10: =SUMIFS('Journal Entries'!$I$5:$I$184,'Journal Entries'!$E$5:$E$184,$A10,'Journal Entries'!$D$5:$D$184,"<=5")-SUMIFS('Journal Entries'!$J$5:$J$184,'Journal Entries'!$E$5:$E$184,$A10,'Journal Entries'!$D$5:$D$184,"<=5") -> -1150 | H10: =SUMIFS('Journal Entries'!$I$5:$I$184,'Journal Entries'!$E$5:$E$184,$A10,'Journal Entries'!$D$5:$D$184,"<=6")-SUMIFS('Journal Entries'!$J$5:$J$184,'Journal Entries'!$E$5:$E$184,$A10,'Journal Entries'!$D$5:$D$184,"<=6") -> -1350
A11: ='Chart of Accounts'!A11 -> 300000 | B11: ='Chart of Accounts'!B11 -> Retained Earnings | C11: =SUMIFS('Journal Entries'!$I$5:$I$184,'Journal Entries'!$E$5:$E$184,$A11,'Journal Entries'!$D$5:$D$184,"<=1")-SUMIFS('Journal Entries'!$J$5:$J$184,'Journal Entries'!$E$5:$E$184,$A11,'Journal Entries'!$D$5:$D$184,"<=1") -> 0 | D11: =SUMIFS('Journal Entries'!$I$5:$I$184,'Journal Entries'!$E$5:$E$184,$A11,'Journal Entries'!$D$5:$D$184,"<=2")-SUMIFS('Journal Entries'!$J$5:$J$184,'Journal Entries'!$E$5:$E$184,$A11,'Journal Entries'!$D$5:$D$184,"<=2") -> 0 | E11: =SUMIFS('Journal Entries'!$I$5:$I$184,'Journal Entries'!$E$5:$E$184,$A11,'Journal Entries'!$D$5:$D$184,"<=3")-SUMIFS('Journal Entries'!$J$5:$J$184,'Journal Entries'!$E$5:$E$184,$A11,'Journal Entries'!$D$5:$D$184,"<=3") -> 0 | F11: =SUMIFS('Journal Entries'!$I$5:$I$184,'Journal Entries'!$E$5:$E$184,$A11,'Journal Entries'!$D$5:$D$184,"<=4")-SUMIFS('Journal Entries'!$J$5:$J$184,'Journal Entries'!$E$5:$E$184,$A11,'Journal Entries'!$D$5:$D$184,"<=4") -> 0 | G11: =SUMIFS('Journal Entries'!$I$5:$I$184,'Journal Entries'!$E$5:$E$184,$A11,'Journal Entries'!$D$5:$D$184,"<=5")-SUMIFS('Journal Entries'!$J$5:$J$184,'Journal Entries'!$E$5:$E$184,$A11,'Journal Entries'!$D$5:$D$184,"<=5") -> 0 | H11: =SUMIFS('Journal Entries'!$I$5:$I$184,'Journal Entries'!$E$5:$E$184,$A11,'Journal Entries'!$D$5:$D$184,"<=6")-SUMIFS('Journal Entries'!$J$5:$J$184,'Journal Entries'!$E$5:$E$184,$A11,'Journal Entries'!$D$5:$D$184,"<=6") -> 0
A12: ='Chart of Accounts'!A12 -> 310000 | B12: ='Chart of Accounts'!B12 -> Owner's Capital | C12: =SUMIFS('Journal Entries'!$I$5:$I$184,'Journal Entries'!$E$5:$E$184,$A12,'Journal Entries'!$D$5:$D$184,"<=1")-SUMIFS('Journal Entries'!$J$5:$J$184,'Journal Entries'!$E$5:$E$184,$A12,'Journal Entries'!$D$5:$D$184,"<=1") -> -20000 | D12: =SUMIFS('Journal Entries'!$I$5:$I$184,'Journal Entries'!$E$5:$E$184,$A12,'Journal Entries'!$D$5:$D$184,"<=2")-SUMIFS('Journal Entries'!$J$5:$J$184,'Journal Entries'!$E$5:$E$184,$A12,'Journal Entries'!$D$5:$D$184,"<=2") -> -20000 | E12: =SUMIFS('Journal Entries'!$I$5:$I$184,'Journal Entries'!$E$5:$E$184,$A12,'Journal Entries'!$D$5:$D$184,"<=3")-SUMIFS('Journal Entries'!$J$5:$J$184,'Journal Entries'!$E$5:$E$184,$A12,'Journal Entries'!$D$5:$D$184,"<=3") -> -20000 | F12: =SUMIFS('Journal Entries'!$I$5:$I$184,'Journal Entries'!$E$5:$E$184,$A12,'Journal Entries'!$D$5:$D$184,"<=4")-SUMIFS('Journal Entries'!$J$5:$J$184,'Journal Entries'!$E$5:$E$184,$A12,'Journal Entries'!$D$5:$D$184,"<=4") -> -20000 | G12: =SUMIFS('Journal Entries'!$I$5:$I$184,'Journal Entries'!$E$5:$E$184,$A12,'Journal Entries'!$D$5:$D$184,"<=5")-SUMIFS('Journal Entries'!$J$5:$J$184,'Journal Entries'!$E$5:$E$184,$A12,'Journal Entries'!$D$5:$D$184,"<=5") -> -20000 | H12: =SUMIFS('Journal Entries'!$I$5:$I$184,'Journal Entries'!$E$5:$E$184,$A12,'Journal Entries'!$D$5:$D$184,"<=6")-SUMIFS('Journal Entries'!$J$5:$J$184,'Journal Entries'!$E$5:$E$184,$A12,'Journal Entries'!$D$5:$D$184,"<=6") -> -20000
A13: ='Chart of Accounts'!A13 -> 400000 | B13: ='Chart of Accounts'!B13 -> Sales Revenue | C13: =SUMIFS('Journal Entries'!$I$5:$I$184,'Journal Entries'!$E$5:$E$184,$A13,'Journal Entries'!$C$5:$C$184,"Jan")-SUMIFS('Journal Entries'!$J$5:$J$184,'Journal Entries'!$E$5:$E$184,$A13,'Journal Entries'!$C$5:$C$184,"Jan") -> -18000 | D13: =SUMIFS('Journal Entries'!$I$5:$I$184,'Journal Entries'!$E$5:$E$184,$A13,'Journal Entries'!$C$5:$C$184,"Feb")-SUMIFS('Journal Entries'!$J$5:$J$184,'Journal Entries'!$E$5:$E$184,$A13,'Journal Entries'!$C$5:$C$184,"Feb") -> -23000 | E13: =SUMIFS('Journal Entries'!$I$5:$I$184,'Journal Entries'!$E$5:$E$184,$A13,'Journal Entries'!$C$5:$C$184,"Mar")-SUMIFS('Journal Entries'!$J$5:$J$184,'Journal Entries'!$E$5:$E$184,$A13,'Journal Entries'!$C$5:$C$184,"Mar") -> -48750 | F13: =SUMIFS('Journal Entries'!$I$5:$I$184,'Journal Entries'!$E$5:$E$184,$A13,'Journal Entries'!$C$5:$C$184,"Apr")-SUMIFS('Journal Entries'!$J$5:$J$184,'Journal Entries'!$E$5:$E$184,$A13,'Journal Entries'!$C$5:$C$184,"Apr") -> -52000 | G13: =SUMIFS('Journal Entries'!$I$5:$I$184,'Journal Entries'!$E$5:$E$184,$A13,'Journal Entries'!$C$5:$C$184,"May")-SUMIFS('Journal Entries'!$J$5:$J$184,'Journal Entries'!$E$5:$E$184,$A13,'Journal Entries'!$C$5:$C$184,"May") -> -58000 | H13: =SUMIFS('Journal Entries'!$I$5:$I$184,'Journal Entries'!$E$5:$E$184,$A13,'Journal Entries'!$C$5:$C$184,"Jun")-SUMIFS('Journal Entries'!$J$5:$J$184,'Journal Entries'!$E$5:$E$184,$A13,'Journal Entries'!$C$5:$C$184,"Jun") -> -63000
A14: ='Chart of Accounts'!A14 -> 500000 | B14: ='Chart of Accounts'!B14 -> Cost of Goods Sold | C14: =SUMIFS('Journal Entries'!$I$5:$I$184,'Journal Entries'!$E$5:$E$184,$A14,'Journal Entries'!$C$5:$C$184,"Jan")-SUMIFS('Journal Entries'!$J$5:$J$184,'Journal Entries'!$E$5:$E$184,$A14,'Journal Entries'!$C$5:$C$184,"Jan") -> 12000 | D14: =SUMIFS('Journal Entries'!$I$5:$I$184,'Journal Entries'!$E$5:$E$184,$A14,'Journal Entries'!$C$5:$C$184,"Feb")-SUMIFS('Journal Entries'!$J$5:$J$184,'Journal Entries'!$E$5:$E$184,$A14,'Journal Entries'!$C$5:$C$184,"Feb") -> 18500 | E14: =SUMIFS('Journal Entries'!$I$5:$I$184,'Journal Entries'!$E$5:$E$184,$A14,'Journal Entries'!$C$5:$C$184,"Mar")-SUMIFS('Journal Entries'!$J$5:$J$184,'Journal Entries'!$E$5:$E$184,$A14,'Journal Entries'!$C$5:$C$184,"Mar") -> 29400 | F14: =SUMIFS('Journal Entries'!$I$5:$I$184,'Journal Entries'!$E$5:$E$184,$A14,'Journal Entries'!$C$5:$C$184,"Apr")-SUMIFS('Journal Entries'!$J$5:$J$184,'Journal Entries'!$E$5:$E$184,$A14,'Journal Entries'!$C$5:$C$184,"Apr") -> 30000 | G14: =SUMIFS('Journal Entries'!$I$5:$I$184,'Journal Entries'!$E$5:$E$184,$A14,'Journal Entries'!$C$5:$C$184,"May")-SUMIFS('Journal Entries'!$J$5:$J$184,'Journal Entries'!$E$5:$E$184,$A14,'Journal Entries'!$C$5:$C$184,"May") -> 32000 | H14: =SUMIFS('Journal Entries'!$I$5:$I$184,'Journal Entries'!$E$5:$E$184,$A14,'Journal Entries'!$C$5:$C$184,"Jun")-SUMIFS('Journal Entries'!$J$5:$J$184,'Journal Entries'!$E$5:$E$184,$A14,'Journal Entries'!$C$5:$C$184,"Jun") -> 34000
A15: ='Chart of Accounts'!A15 -> 600000 | B15: ='Chart of Accounts'!B15 -> Salaries Expense | C15: =SUMIFS('Journal Entries'!$I$5:$I$184,'Journal Entries'!$E$5:$E$184,$A15,'Journal Entries'!$C$5:$C$184,"Jan")-SUMIFS('Journal Entries'!$J$5:$J$184,'Journal Entries'!$E$5:$E$184,$A15,'Journal Entries'!$C$5:$C$184,"Jan") -> 13600 | D15: =SUMIFS('Journal Entries'!$I$5:$I$184,'Journal Entries'!$E$5:$E$184,$A15,'Journal Entries'!$C$5:$C$184,"Feb")-SUMIFS('Journal Entries'!$J$5:$J$184,'Journal Entries'!$E$5:$E$184,$A15,'Journal Entries'!$C$5:$C$184,"Feb") -> 13600 | E15: =SUMIFS('Journal Entries'!$I$5:$I$184,'Journal Entries'!$E$5:$E$184,$A15,'Journal Entries'!$C$5:$C$184,"Mar")-SUMIFS('Journal Entries'!$J$5:$J$184,'Journal Entries'!$E$5:$E$184,$A15,'Journal Entries'!$C$5:$C$184,"Mar") -> 13600 | F15: =SUMIFS('Journal Entries'!$I$5:$I$184,'Journal Entries'!$E$5:$E$184,$A15,'Journal Entries'!$C$5:$C$184,"Apr")-SUMIFS('Journal Entries'!$J$5:$J$184,'Journal Entries'!$E$5:$E$184,$A15,'Journal Entries'!$C$5:$C$184,"Apr") -> 13600 | G15: =SUMIFS('Journal Entries'!$I$5:$I$184,'Journal Entries'!$E$5:$E$184,$A15,'Journal Entries'!$C$5:$C$184,"May")-SUMIFS('Journal Entries'!$J$5:$J$184,'Journal Entries'!$E$5:$E$184,$A15,'Journal Entries'!$C$5:$C$184,"May") -> 13600 | H15: =SUMIFS('Journal Entries'!$I$5:$I$184,'Journal Entries'!$E$5:$E$184,$A15,'Journal Entries'!$C$5:$C$184,"Jun")-SUMIFS('Journal Entries'!$J$5:$J$184,'Journal Entries'!$E$5:$E$184,$A15,'Journal Entries'!$C$5:$C$184,"Jun") -> 13600
A16: ='Chart of Accounts'!A16 -> 610000 | B16: ='Chart of Accounts'!B16 -> Rent Expense | C16: =SUMIFS('Journal Entries'!$I$5:$I$184,'Journal Entries'!$E$5:$E$184,$A16,'Journal Entries'!$C$5:$C$184,"Jan")-SUMIFS('Journal Entries'!$J$5:$J$184,'Journal Entries'!$E$5:$E$184,$A16,'Journal Entries'!$C$5:$C$184,"Jan") -> 3200 | D16: =SUMIFS('Journal Entries'!$I$5:$I$184,'Journal Entries'!$E$5:$E$184,$A16,'Journal Entries'!$C$5:$C$184,"Feb")-SUMIFS('Journal Entries'!$J$5:$J$184,'Journal Entries'!$E$5:$E$184,$A16,'Journal Entries'!$C$5:$C$184,"Feb") -> 3200 | E16: =SUMIFS('Journal Entries'!$I$5:$I$184,'Journal Entries'!$E$5:$E$184,$A16,'Journal Entries'!$C$5:$C$184,"Mar")-SUMIFS('Journal Entries'!$J$5:$J$184,'Journal Entries'!$E$5:$E$184,$A16,'Journal Entries'!$C$5:$C$184,"Mar") -> 3200 | F16: =SUMIFS('Journal Entries'!$I$5:$I$184,'Journal Entries'!$E$5:$E$184,$A16,'Journal Entries'!$C$5:$C$184,"Apr")-SUMIFS('Journal Entries'!$J$5:$J$184,'Journal Entries'!$E$5:$E$184,$A16,'Journal Entries'!$C$5:$C$184,"Apr") -> 3200 | G16: =SUMIFS('Journal Entries'!$I$5:$I$184,'Journal Entries'!$E$5:$E$184,$A16,'Journal Entries'!$C$5:$C$184,"May")-SUMIFS('Journal Entries'!$J$5:$J$184,'Journal Entries'!$E$5:$E$184,$A16,'Journal Entries'!$C$5:$C$184,"May") -> 3200 | H16: =SUMIFS('Journal Entries'!$I$5:$I$184,'Journal Entries'!$E$5:$E$184,$A16,'Journal Entries'!$C$5:$C$184,"Jun")-SUMIFS('Journal Entries'!$J$5:$J$184,'Journal Entries'!$E$5:$E$184,$A16,'Journal Entries'!$C$5:$C$184,"Jun") -> 3200
A17: ='Chart of Accounts'!A17 -> 620000 | B17: ='Chart of Accounts'!B17 -> Utilities Expense | C17: =SUMIFS('Journal Entries'!$I$5:$I$184,'Journal Entries'!$E$5:$E$184,$A17,'Journal Entries'!$C$5:$C$184,"Jan")-SUMIFS('Journal Entries'!$J$5:$J$184,'Journal Entries'!$E$5:$E$184,$A17,'Journal Entries'!$C$5:$C$184,"Jan") -> 1100 | D17: =SUMIFS('Journal Entries'!$I$5:$I$184,'Journal Entries'!$E$5:$E$184,$A17,'Journal Entries'!$C$5:$C$184,"Feb")-SUMIFS('Journal Entries'!$J$5:$J$184,'Journal Entries'!$E$5:$E$184,$A17,'Journal Entries'!$C$5:$C$184,"Feb") -> 1100 | E17: =SUMIFS('Journal Entries'!$I$5:$I$184,'Journal Entries'!$E$5:$E$184,$A17,'Journal Entries'!$C$5:$C$184,"Mar")-SUMIFS('Journal Entries'!$J$5:$J$184,'Journal Entries'!$E$5:$E$184,$A17,'Journal Entries'!$C$5:$C$184,"Mar") -> 1250 | F17: =SUMIFS('Journal Entries'!$I$5:$I$184,'Journal Entries'!$E$5:$E$184,$A17,'Journal Entries'!$C$5:$C$184,"Apr")-SUMIFS('Journal Entries'!$J$5:$J$184,'Journal Entries'!$E$5:$E$184,$A17,'Journal Entries'!$C$5:$C$184,"Apr") -> 1000 | G17: =SUMIFS('Journal Entries'!$I$5:$I$184,'Journal Entries'!$E$5:$E$184,$A17,'Journal Entries'!$C$5:$C$184,"May")-SUMIFS('Journal Entries'!$J$5:$J$184,'Journal Entries'!$E$5:$E$184,$A17,'Journal Entries'!$C$5:$C$184,"May") -> 1050 | H17: =SUMIFS('Journal Entries'!$I$5:$I$184,'Journal Entries'!$E$5:$E$184,$A17,'Journal Entries'!$C$5:$C$184,"Jun")-SUMIFS('Journal Entries'!$J$5:$J$184,'Journal Entries'!$E$5:$E$184,$A17,'Journal Entries'!$C$5:$C$184,"Jun") -> 1100
A18: ='Chart of Accounts'!A18 -> 630000 | B18: ='Chart of Accounts'!B18 -> Office Supplies Expense | C18: =SUMIFS('Journal Entries'!$I$5:$I$184,'Journal Entries'!$E$5:$E$184,$A18,'Journal Entries'!$C$5:$C$184,"Jan")-SUMIFS('Journal Entries'!$J$5:$J$184,'Journal Entries'!$E$5:$E$184,$A18,'Journal Entries'!$C$5:$C$184,"Jan") -> 350 | D18: =SUMIFS('Journal Entries'!$I$5:$I$184,'Journal Entries'!$E$5:$E$184,$A18,'Journal Entries'!$C$5:$C$184,"Feb")-SUMIFS('Journal Entries'!$J$5:$J$184,'Journal Entries'!$E$5:$E$184,$A18,'Journal Entries'!$C$5:$C$184,"Feb") -> 400 | E18: =SUMIFS('Journal Entries'!$I$5:$I$184,'Journal Entries'!$E$5:$E$184,$A18,'Journal Entries'!$C$5:$C$184,"Mar")-SUMIFS('Journal Entries'!$J$5:$J$184,'Journal Entries'!$E$5:$E$184,$A18,'Journal Entries'!$C$5:$C$184,"Mar") -> 480 | F18: =SUMIFS('Journal Entries'!$I$5:$I$184,'Journal Entries'!$E$5:$E$184,$A18,'Journal Entries'!$C$5:$C$184,"Apr")-SUMIFS('Journal Entries'!$J$5:$J$184,'Journal Entries'!$E$5:$E$184,$A18,'Journal Entries'!$C$5:$C$184,"Apr") -> 420 | G18: =SUMIFS('Journal Entries'!$I$5:$I$184,'Journal Entries'!$E$5:$E$184,$A18,'Journal Entries'!$C$5:$C$184,"May")-SUMIFS('Journal Entries'!$J$5:$J$184,'Journal Entries'!$E$5:$E$184,$A18,'Journal Entries'!$C$5:$C$184,"May") -> 400 | H18: =SUMIFS('Journal Entries'!$I$5:$I$184,'Journal Entries'!$E$5:$E$184,$A18,'Journal Entries'!$C$5:$C$184,"Jun")-SUMIFS('Journal Entries'!$J$5:$J$184,'Journal Entries'!$E$5:$E$184,$A18,'Journal Entries'!$C$5:$C$184,"Jun") -> 450
A19: ='Chart of Accounts'!A19 -> 640000 | B19: ='Chart of Accounts'!B19 -> Depreciation Expense | C19: =SUMIFS('Journal Entries'!$I$5:$I$184,'Journal Entries'!$E$5:$E$184,$A19,'Journal Entries'!$C$5:$C$184,"Jan")-SUMIFS('Journal Entries'!$J$5:$J$184,'Journal Entries'!$E$5:$E$184,$A19,'Journal Entries'!$C$5:$C$184,"Jan") -> 900 | D19: =SUMIFS('Journal Entries'!$I$5:$I$184,'Journal Entries'!$E$5:$E$184,$A19,'Journal Entries'!$C$5:$C$184,"Feb")-SUMIFS('Journal Entries'!$J$5:$J$184,'Journal Entries'!$E$5:$E$184,$A19,'Journal Entries'!$C$5:$C$184,"Feb") -> 900 | E19: =SUMIFS('Journal Entries'!$I$5:$I$184,'Journal Entries'!$E$5:$E$184,$A19,'Journal Entries'!$C$5:$C$184,"Mar")-SUMIFS('Journal Entries'!$J$5:$J$184,'Journal Entries'!$E$5:$E$184,$A19,'Journal Entries'!$C$5:$C$184,"Mar") -> 900 | F19: =SUMIFS('Journal Entries'!$I$5:$I$184,'Journal Entries'!$E$5:$E$184,$A19,'Journal Entries'!$C$5:$C$184,"Apr")-SUMIFS('Journal Entries'!$J$5:$J$184,'Journal Entries'!$E$5:$E$184,$A19,'Journal Entries'!$C$5:$C$184,"Apr") -> 900 | G19: =SUMIFS('Journal Entries'!$I$5:$I$184,'Journal Entries'!$E$5:$E$184,$A19,'Journal Entries'!$C$5:$C$184,"May")-SUMIFS('Journal Entries'!$J$5:$J$184,'Journal Entries'!$E$5:$E$184,$A19,'Journal Entries'!$C$5:$C$184,"May") -> 900 | H19: =SUMIFS('Journal Entries'!$I$5:$I$184,'Journal Entries'!$E$5:$E$184,$A19,'Journal Entries'!$C$5:$C$184,"Jun")-SUMIFS('Journal Entries'!$J$5:$J$184,'Journal Entries'!$E$5:$E$184,$A19,'Journal Entries'!$C$5:$C$184,"Jun") -> 900
A20: ='Chart of Accounts'!A20 -> 650000 | B20: ='Chart of Accounts'!B20 -> Marketing Expense | C20: =SUMIFS('Journal Entries'!$I$5:$I$184,'Journal Entries'!$E$5:$E$184,$A20,'Journal Entries'!$C$5:$C$184,"Jan")-SUMIFS('Journal Entries'!$J$5:$J$184,'Journal Entries'!$E$5:$E$184,$A20,'Journal Entries'!$C$5:$C$184,"Jan") -> 700 | D20: =SUMIFS('Journal Entries'!$I$5:$I$184,'Journal Entries'!$E$5:$E$184,$A20,'Journal Entries'!$C$5:$C$184,"Feb")-SUMIFS('Journal Entries'!$J$5:$J$184,'Journal Entries'!$E$5:$E$184,$A20,'Journal Entries'!$C$5:$C$184,"Feb") -> 900 | E20: =SUMIFS('Journal Entries'!$I$5:$I$184,'Journal Entries'!$E$5:$E$184,$A20,'Journal Entries'!$C$5:$C$184,"Mar")-SUMIFS('Journal Entries'!$J$5:$J$184,'Journal Entries'!$E$5:$E$184,$A20,'Journal Entries'!$C$5:$C$184,"Mar") -> 1600 | F20: =SUMIFS('Journal Entries'!$I$5:$I$184,'Journal Entries'!$E$5:$E$184,$A20,'Journal Entries'!$C$5:$C$184,"Apr")-SUMIFS('Journal Entries'!$J$5:$J$184,'Journal Entries'!$E$5:$E$184,$A20,'Journal Entries'!$C$5:$C$184,"Apr") -> 1800 | G20: =SUMIFS('Journal Entries'!$I$5:$I$184,'Journal Entries'!$E$5:$E$184,$A20,'Journal Entries'!$C$5:$C$184,"May")-SUMIFS('Journal Entries'!$J$5:$J$184,'Journal Entries'!$E$5:$E$184,$A20,'Journal Entries'!$C$5:$C$184,"May") -> 2000 | H20: =SUMIFS('Journal Entries'!$I$5:$I$184,'Journal Entries'!$E$5:$E$184,$A20,'Journal Entries'!$C$5:$C$184,"Jun")-SUMIFS('Journal Entries'!$J$5:$J$184,'Journal Entries'!$E$5:$E$184,$A20,'Journal Entries'!$C$5:$C$184,"Jun") -> 2200
B21: BALANCE CHECK (cumulative total debits - credits, all accounts — should be 0) | C21: =SUMIFS('Journal Entries'!$I$5:$I$184,'Journal Entries'!$D$5:$D$184,"<=1")-SUMIFS('Journal Entries'!$J$5:$J$184,'Journal Entries'!$D$5:$D$184,"<=1") -> 0 | D21: =SUMIFS('Journal Entries'!$I$5:$I$184,'Journal Entries'!$D$5:$D$184,"<=2")-SUMIFS('Journal Entries'!$J$5:$J$184,'Journal Entries'!$D$5:$D$184,"<=2") -> 0 | E21: =SUMIFS('Journal Entries'!$I$5:$I$184,'Journal Entries'!$D$5:$D$184,"<=3")-SUMIFS('Journal Entries'!$J$5:$J$184,'Journal Entries'!$D$5:$D$184,"<=3") -> 0 | F21: =SUMIFS('Journal Entries'!$I$5:$I$184,'Journal Entries'!$D$5:$D$184,"<=4")-SUMIFS('Journal Entries'!$J$5:$J$184,'Journal Entries'!$D$5:$D$184,"<=4") -> 0 | G21: =SUMIFS('Journal Entries'!$I$5:$I$184,'Journal Entries'!$D$5:$D$184,"<=5")-SUMIFS('Journal Entries'!$J$5:$J$184,'Journal Entries'!$D$5:$D$184,"<=5") -> 0 | H21: =SUMIFS('Journal Entries'!$I$5:$I$184,'Journal Entries'!$D$5:$D$184,"<=6")-SUMIFS('Journal Entries'!$J$5:$J$184,'Journal Entries'!$D$5:$D$184,"<=6") -> 0
A23: Note: Balance Sheet accounts (Cash, AR, AP, Accum. Depreciation, Equity) show a running/cumulative balance through each month-end. P&L accounts (Revenue, COGS, Opex) show that month's activity only, as in a standard monthly income statement.

Sheet P&L
A1: Profit & Loss Statement
A2: Auto-calculated from Trial Balance, by month (Jan-Jun)
A4: Line | B4: Jan | C4: Feb | D4: Mar | E4: Apr | F4: May | G4: Jun
A5: Revenue | B5: =-'Trial Balance'!C13 -> 18000 | C5: =-'Trial Balance'!D13 -> 23000 | D5: =-'Trial Balance'!E13 -> 48750 | E5: =-'Trial Balance'!F13 -> 52000 | F5: =-'Trial Balance'!G13 -> 58000 | G5: =-'Trial Balance'!H13 -> 63000
A6: Cost of Goods Sold | B6: ='Trial Balance'!C14 -> 12000 | C6: ='Trial Balance'!D14 -> 18500 | D6: ='Trial Balance'!E14 -> 29400 | E6: ='Trial Balance'!F14 -> 30000 | F6: ='Trial Balance'!G14 -> 32000 | G6: ='Trial Balance'!H14 -> 34000
A7: Gross Margin | B7: =B5-B6 -> 6000 | C7: =C5-C6 -> 4500 | D7: =D5-D6 -> 19350 | E7: =E5-E6 -> 22000 | F7: =F5-F6 -> 26000 | G7: =G5-G6 -> 29000
A8: Salaries | B8: ='Trial Balance'!C15 -> 13600 | C8: ='Trial Balance'!D15 -> 13600 | D8: ='Trial Balance'!E15 -> 13600 | E8: ='Trial Balance'!F15 -> 13600 | F8: ='Trial Balance'!G15 -> 13600 | G8: ='Trial Balance'!H15 -> 13600
A9: Rent | B9: ='Trial Balance'!C16 -> 3200 | C9: ='Trial Balance'!D16 -> 3200 | D9: ='Trial Balance'!E16 -> 3200 | E9: ='Trial Balance'!F16 -> 3200 | F9: ='Trial Balance'!G16 -> 3200 | G9: ='Trial Balance'!H16 -> 3200
A10: Utilities | B10: ='Trial Balance'!C17 -> 1100 | C10: ='Trial Balance'!D17 -> 1100 | D10: ='Trial Balance'!E17 -> 1250 | E10: ='Trial Balance'!F17 -> 1000 | F10: ='Trial Balance'!G17 -> 1050 | G10: ='Trial Balance'!H17 -> 1100
A11: Office Supplies | B11: ='Trial Balance'!C18 -> 350 | C11: ='Trial Balance'!D18 -> 400 | D11: ='Trial Balance'!E18 -> 480 | E11: ='Trial Balance'!F18 -> 420 | F11: ='Trial Balance'!G18 -> 400 | G11: ='Trial Balance'!H18 -> 450
A12: Depreciation | B12: ='Trial Balance'!C19 -> 900 | C12: ='Trial Balance'!D19 -> 900 | D12: ='Trial Balance'!E19 -> 900 | E12: ='Trial Balance'!F19 -> 900 | F12: ='Trial Balance'!G19 -> 900 | G12: ='Trial Balance'!H19 -> 900
A13: Marketing | B13: ='Trial Balance'!C20 -> 700 | C13: ='Trial Balance'!D20 -> 900 | D13: ='Trial Balance'!E20 -> 1600 | E13: ='Trial Balance'!F20 -> 1800 | F13: ='Trial Balance'!G20 -> 2000 | G13: ='Trial Balance'!H20 -> 2200
A14: Total Opex | B14: =SUM(B8:B13) -> 19850 | C14: =SUM(C8:C13) -> 20100 | D14: =SUM(D8:D13) -> 21030 | E14: =SUM(E8:E13) -> 20920 | F14: =SUM(F8:F13) -> 21150 | G14: =SUM(G8:G13) -> 21450
A15: Net Income | B15: =B7-B14 -> -13850 | C15: =C7-C14 -> -15600 | D15: =D7-D14 -> -1680 | E15: =E7-E14 -> 1080 | F15: =F7-F14 -> 4850 | G15: =G7-G14 -> 7550

Sheet Cost Center Reporting (BW mock)
A1: Cost Center Reporting
A2: Mock BW query: Cost Center x Category x Month — SUMIFS-based pivot model
A3: Mirrors what a BW query/InfoProvider does: aggregating GL line items by cost center and period for management reporting.
A5: Cost Center | B5: Category | C5: Jan | D5: Feb | E5: Mar | F5: Apr | G5: May | H5: Jun | I5: Jan→Jun Var. | J5: Jan→Jun Var. %
A6: CC-100 | B6: Revenue | C6: =-1*(SUMIFS('Journal Entries'!$I$5:$I$184,'Journal Entries'!$E$5:$E$184,400000,'Journal Entries'!$G$5:$G$184,$A6,'Journal Entries'!$C$5:$C$184,"Jan")-SUMIFS('Journal Entries'!$J$5:$J$184,'Journal Entries'!$E$5:$E$184,400000,'Journal Entries'!$G$5:$G$184,$A6,'Journal Entries'!$C$5:$C$184,"Jan")) -> 18000 | D6: =-1*(SUMIFS('Journal Entries'!$I$5:$I$184,'Journal Entries'!$E$5:$E$184,400000,'Journal Entries'!$G$5:$G$184,$A6,'Journal Entries'!$C$5:$C$184,"Feb")-SUMIFS('Journal Entries'!$J$5:$J$184,'Journal Entries'!$E$5:$E$184,400000,'Journal Entries'!$G$5:$G$184,$A6,'Journal Entries'!$C$5:$C$184,"Feb")) -> 23000 | E6: =-1*(SUMIFS('Journal Entries'!$I$5:$I$184,'Journal Entries'!$E$5:$E$184,400000,'Journal Entries'!$G$5:$G$184,$A6,'Journal Entries'!$C$5:$C$184,"Mar")-SUMIFS('Journal Entries'!$J$5:$J$184,'Journal Entries'!$E$5:$E$184,400000,'Journal Entries'!$G$5:$G$184,$A6,'Journal Entries'!$C$5:$C$184,"Mar")) -> 48750 | F6: =-1*(SUMIFS('Journal Entries'!$I$5:$I$184,'Journal Entries'!$E$5:$E$184,400000,'Journal Entries'!$G$5:$G$184,$A6,'Journal Entries'!$C$5:$C$184,"Apr")-SUMIFS('Journal Entries'!$J$5:$J$184,'Journal Entries'!$E$5:$E$184,400000,'Journal Entries'!$G$5:$G$184,$A6,'Journal Entries'!$C$5:$C$184,"Apr")) -> 52000 | G6: =-1*(SUMIFS('Journal Entries'!$I$5:$I$184,'Journal Entries'!$E$5:$E$184,400000,'Journal Entries'!$G$5:$G$184,$A6,'Journal Entries'!$C$5:$C$184,"May")-SUMIFS('Journal Entries'!$J$5:$J$184,'Journal Entries'!$E$5:$E$184,400000,'Journal Entries'!$G$5:$G$184,$A6,'Journal Entries'!$C$5:$C$184,"May")) -> 58000 | H6: =-1*(SUMIFS('Journal Entries'!$I$5:$I$184,'Journal Entries'!$E$5:$E$184,400000,'Journal Entries'!$G$5:$G$184,$A6,'Journal Entries'!$C$5:$C$184,"Jun")-SUMIFS('Journal Entries'!$J$5:$J$184,'Journal Entries'!$E$5:$E$184,400000,'Journal Entries'!$G$5:$G$184,$A6,'Journal Entries'!$C$5:$C$184,"Jun")) -> 63000 | I6: =H6-C6 -> 45000 | J6: =IFERROR((H6-C6)/ABS(C6),"") -> 2.5
A7: CC-100 | B7: COGS | C7: =(SUMIFS('Journal Entries'!$I$5:$I$184,'Journal Entries'!$E$5:$E$184,500000,'Journal Entries'!$G$5:$G$184,$A7,'Journal Entries'!$C$5:$C$184,"Jan")-SUMIFS('Journal Entries'!$J$5:$J$184,'Journal Entries'!$E$5:$E$184,500000,'Journal Entries'!$G$5:$G$184,$A7,'Journal Entries'!$C$5:$C$184,"Jan")) -> 0 | D7: =(SUMIFS('Journal Entries'!$I$5:$I$184,'Journal Entries'!$E$5:$E$184,500000,'Journal Entries'!$G$5:$G$184,$A7,'Journal Entries'!$C$5:$C$184,"Feb")-SUMIFS('Journal Entries'!$J$5:$J$184,'Journal Entries'!$E$5:$E$184,500000,'Journal Entries'!$G$5:$G$184,$A7,'Journal Entries'!$C$5:$C$184,"Feb")) -> 0 | E7: =(SUMIFS('Journal Entries'!$I$5:$I$184,'Journal Entries'!$E$5:$E$184,500000,'Journal Entries'!$G$5:$G$184,$A7,'Journal Entries'!$C$5:$C$184,"Mar")-SUMIFS('Journal Entries'!$J$5:$J$184,'Journal Entries'!$E$5:$E$184,500000,'Journal Entries'!$G$5:$G$184,$A7,'Journal Entries'!$C$5:$C$184,"Mar")) -> 0 | F7: =(SUMIFS('Journal Entries'!$I$5:$I$184,'Journal Entries'!$E$5:$E$184,500000,'Journal Entries'!$G$5:$G$184,$A7,'Journal Entries'!$C$5:$C$184,"Apr")-SUMIFS('Journal Entries'!$J$5:$J$184,'Journal Entries'!$E$5:$E$184,500000,'Journal Entries'!$G$5:$G$184,$A7,'Journal Entries'!$C$5:$C$184,"Apr")) -> 0 | G7: =(SUMIFS('Journal Entries'!$I$5:$I$184,'Journal Entries'!$E$5:$E$184,500000,'Journal Entries'!$G$5:$G$184,$A7,'Journal Entries'!$C$5:$C$184,"May")-SUMIFS('Journal Entries'!$J$5:$J$184,'Journal Entries'!$E$5:$E$184,500000,'Journal Entries'!$G$5:$G$184,$A7,'Journal Entries'!$C$5:$C$184,"May")) -> 0 | H7: =(SUMIFS('Journal Entries'!$I$5:$I$184,'Journal Entries'!$E$5:$E$184,500000,'Journal Entries'!$G$5:$G$184,$A7,'Journal Entries'!$C$5:$C$184,"Jun")-SUMIFS('Journal Entries'!$J$5:$J$184,'Journal Entries'!$E$5:$E$184,500000,'Journal Entries'!$G$5:$G$184,$A7,'Journal Entries'!$C$5:$C$184,"Jun")) -> 0 | I7: =H7-C7 -> 0 | J7: =IFERROR((H7-C7)/ABS(C7),"")
A8: CC-100 | B8: Opex | C8: =(SUMIFS('Journal Entries'!$I$5:$I$184,'Journal Entries'!$E$5:$E$184,600000,'Journal Entries'!$G$5:$G$184,$A8,'Journal Entries'!$C$5:$C$184,"Jan")-SUMIFS('Journal Entries'!$J$5:$J$184,'Journal Entries'!$E$5:$E$184,600000,'Journal Entries'!$G$5:$G$184,$A8,'Journal Entries'!$C$5:$C$184,"Jan")+SUMIFS('Journal Entries'!$I$5:$I$184,'Journal Entries'!$E$5:$E$184,610000,'Journal Entries'!$G$5:$G$184,$A8,'Journal Entries'!$C$5:$C$184,"Jan")-SUMIFS('Journal Entries'!$J$5:$J$184,'Journal Entries'!$E$5:$E$184,610000,'Journal Entries'!$G$5:$G$184,$A8,'Journal Entries'!$C$5:$C$184,"Jan")+SUMIFS('Journal Entries'!$I$5:$I$184,'Journal Entries'!$E$5:$E$184,620000,'Journal Entries'!$G$5:$G$184,$A8,'Journal Entries'!$C$5:$C$184,"Jan")-SUMIFS('Journal Entries'!$J$5:$J$184,'Journal Entries'!$E$5:$E$184,620000,'Journal Entries'!$G$5:$G$184,$A8,'Journal Entries'!$C$5:$C$184,"Jan")+SUMIFS('Journal Entries'!$I$5:$I$184,'Journal Entries'!$E$5:$E$184,630000,'Journal Entries'!$G$5:$G$184,$A8,'Journal Entries'!$C$5:$C$184,"Jan")-SUMIFS('Journal Entries'!$J$5:$J$184,'Journal Entries'!$E$5:$E$184,630000,'Journal Entries'!$G$5:$G$184,$A8,'Journal Entries'!$C$5:$C$184,"Jan")+SUMIFS('Journal Entries'!$I$5:$I$184,'Journal Entries'!$E$5:$E$184,640000,'Journal Entries'!$G$5:$G$184,$A8,'Journal Entries'!$C$5:$C$184,"Jan")-SUMIFS('Journal Entries'!$J$5:$J$184,'Journal Entries'!$E$5:$E$184,640000,'Journal Entries'!$G$5:$G$184,$A8,'Journal Entries'!$C$5:$C$184,"Jan")+SUMIFS('Journal Entries'!$I$5:$I$184,'Journal Entries'!$E$5:$E$184,650000,'Journal Entries'!$G$5:$G$184,$A8,'Journal Entries'!$C$5:$C$184,"Jan")-SUMIFS('Journal Entries'!$J$5:$J$184,'Journal Entries'!$E$5:$E$184,650000,'Journal Entries'!$G$5:$G$184,$A8,'Journal Entries'!$C$5:$C$184,"Jan")) -> 5900 | D8: =(SUMIFS('Journal Entries'!$I$5:$I$184,'Journal Entries'!$E$5:$E$184,600000,'Journal Entries'!$G$5:$G$184,$A8,'Journal Entries'!$C$5:$C$184,"Feb")-SUMIFS('Journal Entries'!$J$5:$J$184,'Journal Entries'!$E$5:$E$184,600000,'Journal Entries'!$G$5:$G$184,$A8,'Journal Entries'!$C$5:$C$184,"Feb")+SUMIFS('Journal Entries'!$I$5:$I$184,'Journal Entries'!$E$5:$E$184,610000,'Journal Entries'!$G$5:$G$184,$A8,'Journal Entries'!$C$5:$C$184,"Feb")-SUMIFS('Journal Entries'!$J$5:$J$184,'Journal Entries'!$E$5:$E$184,610000,'Journal Entries'!$G$5:$G$184,$A8,'Journal Entries'!$C$5:$C$184,"Feb")+SUMIFS('Journal Entries'!$I$5:$I$184,'Journal Entries'!$E$5:$E$184,620000,'Journal Entries'!$G$5:$G$184,$A8,'Journal Entries'!$C$5:$C$184,"Feb")-SUMIFS('Journal Entries'!$J$5:$J$184,'Journal Entries'!$E$5:$E$184,620000,'Journal Entries'!$G$5:$G$184,$A8,'Journal Entries'!$C$5:$C$184,"Feb")+SUMIFS('Journal Entries'!$I$5:$I$184,'Journal Entries'!$E$5:$E$184,630000,'Journal Entries'!$G$5:$G$184,$A8,'Journal Entries'!$C$5:$C$184,"Feb")-SUMIFS('Journal Entries'!$J$5:$J$184,'Journal Entries'!$E$5:$E$184,630000,'Journal Entries'!$G$5:$G$184,$A8,'Journal Entries'!$C$5:$C$184,"Feb")+SUMIFS('Journal Entries'!$I$5:$I$184,'Journal Entries'!$E$5:$E$184,640000,'Journal Entries'!$G$5:$G$184,$A8,'Journal Entries'!$C$5:$C$184,"Feb")-SUMIFS('Journal Entries'!$J$5:$J$184,'Journal Entries'!$E$5:$E$184,640000,'Journal Entries'!$G$5:$G$184,$A8,'Journal Entries'!$C$5:$C$184,"Feb")+SUMIFS('Journal Entries'!$I$5:$I$184,'Journal Entries'!$E$5:$E$184,650000,'Journal Entries'!$G$5:$G$184,$A8,'Journal Entries'!$C$5:$C$184,"Feb")-SUMIFS('Journal Entries'!$J$5:$J$184,'Journal Entries'!$E$5:$E$184,650000,'Journal Entries'!$G$5:$G$184,$A8,'Journal Entries'!$C$5:$C$184,"Feb")) -> 6100 | E8: =(SUMIFS('Journal Entries'!$I$5:$I$184,'Journal Entries'!$E$5:$E$184,600000,'Journal Entries'!$G$5:$G$184,$A8,'Journal Entries'!$C$5:$C$184,"Mar")-SUMIFS('Journal Entries'!$J$5:$J$184,'Journal Entries'!$E$5:$E$184,600000,'Journal Entries'!$G$5:$G$184,$A8,'Journal Entries'!$C$5:$C$184,"Mar")+SUMIFS('Journal Entries'!$I$5:$I$184,'Journal Entries'!$E$5:$E$184,610000,'Journal Entries'!$G$5:$G$184,$A8,'Journal Entries'!$C$5:$C$184,"Mar")-SUMIFS('Journal Entries'!$J$5:$J$184,'Journal Entries'!$E$5:$E$184,610000,'Journal Entries'!$G$5:$G$184,$A8,'Journal Entries'!$C$5:$C$184,"Mar")+SUMIFS('Journal Entries'!$I$5:$I$184,'Journal Entries'!$E$5:$E$184,620000,'Journal Entries'!$G$5:$G$184,$A8,'Journal Entries'!$C$5:$C$184,"Mar")-SUMIFS('Journal Entries'!$J$5:$J$184,'Journal Entries'!$E$5:$E$184,620000,'Journal Entries'!$G$5:$G$184,$A8,'Journal Entries'!$C$5:$C$184,"Mar")+SUMIFS('Journal Entries'!$I$5:$I$184,'Journal Entries'!$E$5:$E$184,630000,'Journal Entries'!$G$5:$G$184,$A8,'Journal Entries'!$C$5:$C$184,"Mar")-SUMIFS('Journal Entries'!$J$5:$J$184,'Journal Entries'!$E$5:$E$184,630000,'Journal Entries'!$G$5:$G$184,$A8,'Journal Entries'!$C$5:$C$184,"Mar")+SUMIFS('Journal Entries'!$I$5:$I$184,'Journal Entries'!$E$5:$E$184,640000,'Journal Entries'!$G$5:$G$184,$A8,'Journal Entries'!$C$5:$C$184,"Mar")-SUMIFS('Journal Entries'!$J$5:$J$184,'Journal Entries'!$E$5:$E$184,640000,'Journal Entries'!$G$5:$G$184,$A8,'Journal Entries'!$C$5:$C$184,"Mar")+SUMIFS('Journal Entries'!$I$5:$I$184,'Journal Entries'!$E$5:$E$184,650000,'Journal Entries'!$G$5:$G$184,$A8,'Journal Entries'!$C$5:$C$184,"Mar")-SUMIFS('Journal Entries'!$J$5:$J$184,'Journal Entries'!$E$5:$E$184,650000,'Journal Entries'!$G$5:$G$184,$A8,'Journal Entries'!$C$5:$C$184,"Mar")) -> 6800 | F8: =(SUMIFS('Journal Entries'!$I$5:$I$184,'Journal Entries'!$E$5:$E$184,600000,'Journal Entries'!$G$5:$G$184,$A8,'Journal Entries'!$C$5:$C$184,"Apr")-SUMIFS('Journal Entries'!$J$5:$J$184,'Journal Entries'!$E$5:$E$184,600000,'Journal Entries'!$G$5:$G$184,$A8,'Journal Entries'!$C$5:$C$184,"Apr")+SUMIFS('Journal Entries'!$I$5:$I$184,'Journal Entries'!$E$5:$E$184,610000,'Journal Entries'!$G$5:$G$184,$A8,'Journal Entries'!$C$5:$C$184,"Apr")-SUMIFS('Journal Entries'!$J$5:$J$184,'Journal Entries'!$E$5:$E$184,610000,'Journal Entries'!$G$5:$G$184,$A8,'Journal Entries'!$C$5:$C$184,"Apr")+SUMIFS('Journal Entries'!$I$5:$I$184,'Journal Entries'!$E$5:$E$184,620000,'Journal Entries'!$G$5:$G$184,$A8,'Journal Entries'!$C$5:$C$184,"Apr")-SUMIFS('Journal Entries'!$J$5:$J$184,'Journal Entries'!$E$5:$E$184,620000,'Journal Entries'!$G$5:$G$184,$A8,'Journal Entries'!$C$5:$C$184,"Apr")+SUMIFS('Journal Entries'!$I$5:$I$184,'Journal Entries'!$E$5:$E$184,630000,'Journal Entries'!$G$5:$G$184,$A8,'Journal Entries'!$C$5:$C$184,"Apr")-SUMIFS('Journal Entries'!$J$5:$J$184,'Journal Entries'!$E$5:$E$184,630000,'Journal Entries'!$G$5:$G$184,$A8,'Journal Entries'!$C$5:$C$184,"Apr")+SUMIFS('Journal Entries'!$I$5:$I$184,'Journal Entries'!$E$5:$E$184,640000,'Journal Entries'!$G$5:$G$184,$A8,'Journal Entries'!$C$5:$C$184,"Apr")-SUMIFS('Journal Entries'!$J$5:$J$184,'Journal Entries'!$E$5:$E$184,640000,'Journal Entries'!$G$5:$G$184,$A8,'Journal Entries'!$C$5:$C$184,"Apr")+SUMIFS('Journal Entries'!$I$5:$I$184,'Journal Entries'!$E$5:$E$184,650000,'Journal Entries'!$G$5:$G$184,$A8,'Journal Entries'!$C$5:$C$184,"Apr")-SUMIFS('Journal Entries'!$J$5:$J$184,'Journal Entries'!$E$5:$E$184,650000,'Journal Entries'!$G$5:$G$184,$A8,'Journal Entries'!$C$5:$C$184,"Apr")) -> 7000 | G8: =(SUMIFS('Journal Entries'!$I$5:$I$184,'Journal Entries'!$E$5:$E$184,600000,'Journal Entries'!$G$5:$G$184,$A8,'Journal Entries'!$C$5:$C$184,"May")-SUMIFS('Journal Entries'!$J$5:$J$184,'Journal Entries'!$E$5:$E$184,600000,'Journal Entries'!$G$5:$G$184,$A8,'Journal Entries'!$C$5:$C$184,"May")+SUMIFS('Journal Entries'!$I$5:$I$184,'Journal Entries'!$E$5:$E$184,610000,'Journal Entries'!$G$5:$G$184,$A8,'Journal Entries'!$C$5:$C$184,"May")-SUMIFS('Journal Entries'!$J$5:$J$184,'Journal Entries'!$E$5:$E$184,610000,'Journal Entries'!$G$5:$G$184,$A8,'Journal Entries'!$C$5:$C$184,"May")+SUMIFS('Journal Entries'!$I$5:$I$184,'Journal Entries'!$E$5:$E$184,620000,'Journal Entries'!$G$5:$G$184,$A8,'Journal Entries'!$C$5:$C$184,"May")-SUMIFS('Journal Entries'!$J$5:$J$184,'Journal Entries'!$E$5:$E$184,620000,'Journal Entries'!$G$5:$G$184,$A8,'Journal Entries'!$C$5:$C$184,"May")+SUMIFS('Journal Entries'!$I$5:$I$184,'Journal Entries'!$E$5:$E$184,630000,'Journal Entries'!$G$5:$G$184,$A8,'Journal Entries'!$C$5:$C$184,"May")-SUMIFS('Journal Entries'!$J$5:$J$184,'Journal Entries'!$E$5:$E$184,630000,'Journal Entries'!$G$5:$G$184,$A8,'Journal Entries'!$C$5:$C$184,"May")+SUMIFS('Journal Entries'!$I$5:$I$184,'Journal Entries'!$E$5:$E$184,640000,'Journal Entries'!$G$5:$G$184,$A8,'Journal Entries'!$C$5:$C$184,"May")-SUMIFS('Journal Entries'!$J$5:$J$184,'Journal Entries'!$E$5:$E$184,640000,'Journal Entries'!$G$5:$G$184,$A8,'Journal Entries'!$C$5:$C$184,"May")+SUMIFS('Journal Entries'!$I$5:$I$184,'Journal Entries'!$E$5:$E$184,650000,'Journal Entries'!$G$5:$G$184,$A8,'Journal Entries'!$C$5:$C$184,"May")-SUMIFS('Journal Entries'!$J$5:$J$184,'Journal Entries'!$E$5:$E$184,650000,'Journal Entries'!$G$5:$G$184,$A8,'Journal Entries'!$C$5:$C$184,"May")) -> 7200 | H8: =(SUMIFS('Journal Entries'!$I$5:$I$184,'Journal Entries'!$E$5:$E$184,600000,'Journal Entries'!$G$5:$G$184,$A8,'Journal Entries'!$C$5:$C$184,"Jun")-SUMIFS('Journal Entries'!$J$5:$J$184,'Journal Entries'!$E$5:$E$184,600000,'Journal Entries'!$G$5:$G$184,$A8,'Journal Entries'!$C$5:$C$184,"Jun")+SUMIFS('Journal Entries'!$I$5:$I$184,'Journal Entries'!$E$5:$E$184,610000,'Journal Entries'!$G$5:$G$184,$A8,'Journal Entries'!$C$5:$C$184,"Jun")-SUMIFS('Journal Entries'!$J$5:$J$184,'Journal Entries'!$E$5:$E$184,610000,'Journal Entries'!$G$5:$G$184,$A8,'Journal Entries'!$C$5:$C$184,"Jun")+SUMIFS('Journal Entries'!$I$5:$I$184,'Journal Entries'!$E$5:$E$184,620000,'Journal Entries'!$G$5:$G$184,$A8,'Journal Entries'!$C$5:$C$184,"Jun")-SUMIFS('Journal Entries'!$J$5:$J$184,'Journal Entries'!$E$5:$E$184,620000,'Journal Entries'!$G$5:$G$184,$A8,'Journal Entries'!$C$5:$C$184,"Jun")+SUMIFS('Journal Entries'!$I$5:$I$184,'Journal Entries'!$E$5:$E$184,630000,'Journal Entries'!$G$5:$G$184,$A8,'Journal Entries'!$C$5:$C$184,"Jun")-SUMIFS('Journal Entries'!$J$5:$J$184,'Journal Entries'!$E$5:$E$184,630000,'Journal Entries'!$G$5:$G$184,$A8,'Journal Entries'!$C$5:$C$184,"Jun")+SUMIFS('Journal Entries'!$I$5:$I$184,'Journal Entries'!$E$5:$E$184,640000,'Journal Entries'!$G$5:$G$184,$A8,'Journal Entries'!$C$5:$C$184,"Jun")-SUMIFS('Journal Entries'!$J$5:$J$184,'Journal Entries'!$E$5:$E$184,640000,'Journal Entries'!$G$5:$G$184,$A8,'Journal Entries'!$C$5:$C$184,"Jun")+SUMIFS('Journal Entries'!$I$5:$I$184,'Journal Entries'!$E$5:$E$184,650000,'Journal Entries'!$G$5:$G$184,$A8,'Journal Entries'!$C$5:$C$184,"Jun")-SUMIFS('Journal Entries'!$J$5:$J$184,'Journal Entries'!$E$5:$E$184,650000,'Journal Entries'!$G$5:$G$184,$A8,'Journal Entries'!$C$5:$C$184,"Jun")) -> 7400 | I8: =H8-C8 -> 1500 | J8: =IFERROR((H8-C8)/ABS(C8),"") -> 0.25423729
A9: CC-200 | B9: Revenue | C9: =-1*(SUMIFS('Journal Entries'!$I$5:$I$184,'Journal Entries'!$E$5:$E$184,400000,'Journal Entries'!$G$5:$G$184,$A9,'Journal Entries'!$C$5:$C$184,"Jan")-SUMIFS('Journal Entries'!$J$5:$J$184,'Journal Entries'!$E$5:$E$184,400000,'Journal Entries'!$G$5:$G$184,$A9,'Journal Entries'!$C$5:$C$184,"Jan")) -> 0 | D9: =-1*(SUMIFS('Journal Entries'!$I$5:$I$184,'Journal Entries'!$E$5:$E$184,400000,'Journal Entries'!$G$5:$G$184,$A9,'Journal Entries'!$C$5:$C$184,"Feb")-SUMIFS('Journal Entries'!$J$5:$J$184,'Journal Entries'!$E$5:$E$184,400000,'Journal Entries'!$G$5:$G$184,$A9,'Journal Entries'!$C$5:$C$184,"Feb")) -> 0 | E9: =-1*(SUMIFS('Journal Entries'!$I$5:$I$184,'Journal Entries'!$E$5:$E$184,400000,'Journal Entries'!$G$5:$G$184,$A9,'Journal Entries'!$C$5:$C$184,"Mar")-SUMIFS('Journal Entries'!$J$5:$J$184,'Journal Entries'!$E$5:$E$184,400000,'Journal Entries'!$G$5:$G$184,$A9,'Journal Entries'!$C$5:$C$184,"Mar")) -> 0 | F9: =-1*(SUMIFS('Journal Entries'!$I$5:$I$184,'Journal Entries'!$E$5:$E$184,400000,'Journal Entries'!$G$5:$G$184,$A9,'Journal Entries'!$C$5:$C$184,"Apr")-SUMIFS('Journal Entries'!$J$5:$J$184,'Journal Entries'!$E$5:$E$184,400000,'Journal Entries'!$G$5:$G$184,$A9,'Journal Entries'!$C$5:$C$184,"Apr")) -> 0 | G9: =-1*(SUMIFS('Journal Entries'!$I$5:$I$184,'Journal Entries'!$E$5:$E$184,400000,'Journal Entries'!$G$5:$G$184,$A9,'Journal Entries'!$C$5:$C$184,"May")-SUMIFS('Journal Entries'!$J$5:$J$184,'Journal Entries'!$E$5:$E$184,400000,'Journal Entries'!$G$5:$G$184,$A9,'Journal Entries'!$C$5:$C$184,"May")) -> 0 | H9: =-1*(SUMIFS('Journal Entries'!$I$5:$I$184,'Journal Entries'!$E$5:$E$184,400000,'Journal Entries'!$G$5:$G$184,$A9,'Journal Entries'!$C$5:$C$184,"Jun")-SUMIFS('Journal Entries'!$J$5:$J$184,'Journal Entries'!$E$5:$E$184,400000,'Journal Entries'!$G$5:$G$184,$A9,'Journal Entries'!$C$5:$C$184,"Jun")) -> 0 | I9: =H9-C9 -> 0 | J9: =IFERROR((H9-C9)/ABS(C9),"")
A10: CC-200 | B10: COGS | C10: =(SUMIFS('Journal Entries'!$I$5:$I$184,'Journal Entries'!$E$5:$E$184,500000,'Journal Entries'!$G$5:$G$184,$A10,'Journal Entries'!$C$5:$C$184,"Jan")-SUMIFS('Journal Entries'!$J$5:$J$184,'Journal Entries'!$E$5:$E$184,500000,'Journal Entries'!$G$5:$G$184,$A10,'Journal Entries'!$C$5:$C$184,"Jan")) -> 12000 | D10: =(SUMIFS('Journal Entries'!$I$5:$I$184,'Journal Entries'!$E$5:$E$184,500000,'Journal Entries'!$G$5:$G$184,$A10,'Journal Entries'!$C$5:$C$184,"Feb")-SUMIFS('Journal Entries'!$J$5:$J$184,'Journal Entries'!$E$5:$E$184,500000,'Journal Entries'!$G$5:$G$184,$A10,'Journal Entries'!$C$5:$C$184,"Feb")) -> 18500 | E10: =(SUMIFS('Journal Entries'!$I$5:$I$184,'Journal Entries'!$E$5:$E$184,500000,'Journal Entries'!$G$5:$G$184,$A10,'Journal Entries'!$C$5:$C$184,"Mar")-SUMIFS('Journal Entries'!$J$5:$J$184,'Journal Entries'!$E$5:$E$184,500000,'Journal Entries'!$G$5:$G$184,$A10,'Journal Entries'!$C$5:$C$184,"Mar")) -> 29400 | F10: =(SUMIFS('Journal Entries'!$I$5:$I$184,'Journal Entries'!$E$5:$E$184,500000,'Journal Entries'!$G$5:$G$184,$A10,'Journal Entries'!$C$5:$C$184,"Apr")-SUMIFS('Journal Entries'!$J$5:$J$184,'Journal Entries'!$E$5:$E$184,500000,'Journal Entries'!$G$5:$G$184,$A10,'Journal Entries'!$C$5:$C$184,"Apr")) -> 30000 | G10: =(SUMIFS('Journal Entries'!$I$5:$I$184,'Journal Entries'!$E$5:$E$184,500000,'Journal Entries'!$G$5:$G$184,$A10,'Journal Entries'!$C$5:$C$184,"May")-SUMIFS('Journal Entries'!$J$5:$J$184,'Journal Entries'!$E$5:$E$184,500000,'Journal Entries'!$G$5:$G$184,$A10,'Journal Entries'!$C$5:$C$184,"May")) -> 32000 | H10: =(SUMIFS('Journal Entries'!$I$5:$I$184,'Journal Entries'!$E$5:$E$184,500000,'Journal Entries'!$G$5:$G$184,$A10,'Journal Entries'!$C$5:$C$184,"Jun")-SUMIFS('Journal Entries'!$J$5:$J$184,'Journal Entries'!$E$5:$E$184,500000,'Journal Entries'!$G$5:$G$184,$A10,'Journal Entries'!$C$5:$C$184,"Jun")) -> 34000 | I10: =H10-C10 -> 22000 | J10: =IFERROR((H10-C10)/ABS(C10),"") -> 1.8333333
